[2023-02-02 11:22:53,194] {taskinstance.py:1159} INFO - Dependencies all met for <TaskInstance: 7_dataproc_subdags.par_task.avg_tincome scheduled__2023-02-01T00:00:00+00:00 [queued]>
[2023-02-02 11:22:53,208] {taskinstance.py:1159} INFO - Dependencies all met for <TaskInstance: 7_dataproc_subdags.par_task.avg_tincome scheduled__2023-02-01T00:00:00+00:00 [queued]>
[2023-02-02 11:22:53,209] {taskinstance.py:1356} INFO - 
--------------------------------------------------------------------------------
[2023-02-02 11:22:53,209] {taskinstance.py:1357} INFO - Starting attempt 1 of 1
[2023-02-02 11:22:53,210] {taskinstance.py:1358} INFO - 
--------------------------------------------------------------------------------
[2023-02-02 11:22:53,240] {taskinstance.py:1377} INFO - Executing <Task(DataprocSubmitJobOperator): avg_tincome> on 2023-02-01 00:00:00+00:00
[2023-02-02 11:22:53,242] {standard_task_runner.py:52} INFO - Started process 20198 to run task
[2023-02-02 11:22:53,244] {standard_task_runner.py:79} INFO - Running: ['airflow', 'tasks', 'run', '7_dataproc_subdags.par_task', 'avg_tincome', 'scheduled__2023-02-01T00:00:00+00:00', '--job-id', '194', '--raw', '--subdir', 'DAGS_FOLDER/Airflow2_0_De_0_a_Heroe/7_dataproc_subdags.py', '--cfg-path', '/tmp/tmpfpe_ctog', '--error-file', '/tmp/tmp3jphxct0']
[2023-02-02 11:22:53,245] {standard_task_runner.py:80} INFO - Job 194: Subtask avg_tincome
[2023-02-02 11:22:53,307] {task_command.py:369} INFO - Running <TaskInstance: 7_dataproc_subdags.par_task.avg_tincome scheduled__2023-02-01T00:00:00+00:00 [running]> on host Tinmar.
[2023-02-02 11:22:53,411] {taskinstance.py:1569} INFO - Exporting the following env vars:
AIRFLOW_CTX_DAG_OWNER=David Sanchez
AIRFLOW_CTX_DAG_ID=7_dataproc_subdags.par_task
AIRFLOW_CTX_TASK_ID=avg_tincome
AIRFLOW_CTX_EXECUTION_DATE=2023-02-01T00:00:00+00:00
AIRFLOW_CTX_TRY_NUMBER=1
AIRFLOW_CTX_DAG_RUN_ID=scheduled__2023-02-01T00:00:00+00:00
[2023-02-02 11:22:53,412] {dataproc.py:1866} INFO - Submitting job
[2023-02-02 11:22:53,425] {base.py:68} INFO - Using connection ID 'google_cloud_default' for task execution.
[2023-02-02 11:22:53,969] {taskinstance.py:1889} ERROR - Task failed with exception
Traceback (most recent call last):
  File "/home/tinmar/.local/lib/python3.10/site-packages/google/api_core/grpc_helpers.py", line 50, in error_remapped_callable
    return callable_(*args, **kwargs)
  File "/home/tinmar/.local/lib/python3.10/site-packages/grpc/_channel.py", line 946, in __call__
    return _end_unary_response_blocking(state, call, False, None)
  File "/home/tinmar/.local/lib/python3.10/site-packages/grpc/_channel.py", line 849, in _end_unary_response_blocking
    raise _InactiveRpcError(state)
grpc._channel._InactiveRpcError: <_InactiveRpcError of RPC that terminated with:
	status = StatusCode.NOT_FOUND
	details = "Not found: Cluster projects/serene-gradient-371719/regions/us-central1/clusters/airflow-spark-cluster"
	debug_error_string = "UNKNOWN:Error received from peer ipv4:142.251.34.138:443 {grpc_message:"Not found: Cluster projects/serene-gradient-371719/regions/us-central1/clusters/airflow-spark-cluster", grpc_status:5, created_time:"2023-02-02T11:22:53.968858689-06:00"}"
>

The above exception was the direct cause of the following exception:

Traceback (most recent call last):
  File "/home/tinmar/.local/lib/python3.10/site-packages/airflow/providers/google/cloud/operators/dataproc.py", line 1868, in execute
    job_object = self.hook.submit_job(
  File "/home/tinmar/.local/lib/python3.10/site-packages/airflow/providers/google/common/hooks/base_google.py", line 462, in inner_wrapper
    return func(self, *args, **kwargs)
  File "/home/tinmar/.local/lib/python3.10/site-packages/airflow/providers/google/cloud/hooks/dataproc.py", line 780, in submit_job
    return client.submit_job(
  File "/home/tinmar/.local/lib/python3.10/site-packages/google/cloud/dataproc_v1/services/job_controller/client.py", line 520, in submit_job
    response = rpc(
  File "/home/tinmar/.local/lib/python3.10/site-packages/google/api_core/gapic_v1/method.py", line 154, in __call__
    return wrapped_func(*args, **kwargs)
  File "/home/tinmar/.local/lib/python3.10/site-packages/google/api_core/retry.py", line 283, in retry_wrapped_func
    return retry_target(
  File "/home/tinmar/.local/lib/python3.10/site-packages/google/api_core/retry.py", line 190, in retry_target
    return target()
  File "/home/tinmar/.local/lib/python3.10/site-packages/google/api_core/grpc_helpers.py", line 52, in error_remapped_callable
    raise exceptions.from_grpc_error(exc) from exc
google.api_core.exceptions.NotFound: 404 Not found: Cluster projects/serene-gradient-371719/regions/us-central1/clusters/airflow-spark-cluster
[2023-02-02 11:22:53,988] {taskinstance.py:1395} INFO - Marking task as FAILED. dag_id=7_dataproc_subdags.par_task, task_id=avg_tincome, execution_date=20230201T000000, start_date=20230202T172253, end_date=20230202T172253
[2023-02-02 11:22:54,022] {standard_task_runner.py:92} ERROR - Failed to execute job 194 for task avg_tincome (404 Not found: Cluster projects/serene-gradient-371719/regions/us-central1/clusters/airflow-spark-cluster; 20198)
[2023-02-02 11:22:54,034] {local_task_job.py:156} INFO - Task exited with return code 1
