[2023-01-31 12:55:13,617] {taskinstance.py:1159} INFO - Dependencies all met for <TaskInstance: 2.3_azure_storage_bigquery.transferir_azure scheduled__2023-01-30T00:00:00+00:00 [queued]>
[2023-01-31 12:55:13,635] {taskinstance.py:1159} INFO - Dependencies all met for <TaskInstance: 2.3_azure_storage_bigquery.transferir_azure scheduled__2023-01-30T00:00:00+00:00 [queued]>
[2023-01-31 12:55:13,636] {taskinstance.py:1356} INFO - 
--------------------------------------------------------------------------------
[2023-01-31 12:55:13,638] {taskinstance.py:1357} INFO - Starting attempt 6 of 6
[2023-01-31 12:55:13,639] {taskinstance.py:1358} INFO - 
--------------------------------------------------------------------------------
[2023-01-31 12:55:13,671] {taskinstance.py:1377} INFO - Executing <Task(AzureBlobStorageToGCSOperator): transferir_azure> on 2023-01-30 00:00:00+00:00
[2023-01-31 12:55:13,675] {standard_task_runner.py:52} INFO - Started process 6802 to run task
[2023-01-31 12:55:13,678] {standard_task_runner.py:79} INFO - Running: ['airflow', 'tasks', 'run', '2.3_azure_storage_bigquery', 'transferir_azure', 'scheduled__2023-01-30T00:00:00+00:00', '--job-id', '57', '--raw', '--subdir', 'DAGS_FOLDER/Airflow2.0-De-0-a-Heroe/2.3_azure_storage_bigquery.py', '--cfg-path', '/tmp/tmpa28ginpt', '--error-file', '/tmp/tmpf91lwnjz']
[2023-01-31 12:55:13,679] {standard_task_runner.py:80} INFO - Job 57: Subtask transferir_azure
[2023-01-31 12:55:13,779] {task_command.py:369} INFO - Running <TaskInstance: 2.3_azure_storage_bigquery.transferir_azure scheduled__2023-01-30T00:00:00+00:00 [running]> on host Tinmar.
[2023-01-31 12:55:13,908] {taskinstance.py:1569} INFO - Exporting the following env vars:
AIRFLOW_CTX_DAG_OWNER=Rodrigo N
AIRFLOW_CTX_DAG_ID=2.3_azure_storage_bigquery
AIRFLOW_CTX_TASK_ID=transferir_azure
AIRFLOW_CTX_EXECUTION_DATE=2023-01-30T00:00:00+00:00
AIRFLOW_CTX_TRY_NUMBER=6
AIRFLOW_CTX_DAG_RUN_ID=scheduled__2023-01-30T00:00:00+00:00
[2023-01-31 12:55:13,926] {base.py:68} INFO - Using connection ID 'wasb_default' for task execution.
[2023-01-31 12:55:13,943] {base.py:68} INFO - Using connection ID 'google_cloud_default' for task execution.
[2023-01-31 12:55:13,944] {azure_blob_to_gcs.py:108} INFO - Downloading data from blob: retail_2020_azure.csv
[2023-01-31 12:55:14,421] {taskinstance.py:1889} ERROR - Task failed with exception
Traceback (most recent call last):
  File "/home/tinmar/.local/lib/python3.10/site-packages/airflow/providers/microsoft/azure/transfers/azure_blob_to_gcs.py", line 109, in execute
    azure_hook.get_file(
  File "/home/tinmar/.local/lib/python3.10/site-packages/airflow/providers/microsoft/azure/hooks/wasb.py", line 344, in get_file
    stream = self.download(container_name=container_name, blob_name=blob_name, **kwargs)
  File "/home/tinmar/.local/lib/python3.10/site-packages/airflow/providers/microsoft/azure/hooks/wasb.py", line 399, in download
    return blob_client.download_blob(offset=offset, length=length, **kwargs)
  File "/home/tinmar/.local/lib/python3.10/site-packages/azure/core/tracing/decorator.py", line 78, in wrapper_use_tracer
    return func(*args, **kwargs)
  File "/home/tinmar/.local/lib/python3.10/site-packages/azure/storage/blob/_blob_client.py", line 905, in download_blob
    return StorageStreamDownloader(**options)
  File "/home/tinmar/.local/lib/python3.10/site-packages/azure/storage/blob/_download.py", line 366, in __init__
    self._response = self._initial_request()
  File "/home/tinmar/.local/lib/python3.10/site-packages/azure/storage/blob/_download.py", line 466, in _initial_request
    process_storage_error(error)
  File "/home/tinmar/.local/lib/python3.10/site-packages/azure/storage/blob/_shared/response_handlers.py", line 185, in process_storage_error
    exec("raise error from None")   # pylint: disable=exec-used # nosec
  File "<string>", line 1, in <module>
azure.core.exceptions.ClientAuthenticationError: Server failed to authenticate the request. Make sure the value of Authorization header is formed correctly including the signature.
RequestId:38725036-d01e-005b-13a8-3598c6000000
Time:2023-01-31T19:17:50.3508473Z
ErrorCode:AuthenticationFailed
authenticationerrordetail:Request date header too old: 'Tue, 31 Jan 2023 18:55:13 GMT'
Content: <?xml version="1.0" encoding="utf-8"?><Error><Code>AuthenticationFailed</Code><Message>Server failed to authenticate the request. Make sure the value of Authorization header is formed correctly including the signature.
RequestId:38725036-d01e-005b-13a8-3598c6000000
Time:2023-01-31T19:17:50.3508473Z</Message><AuthenticationErrorDetail>Request date header too old: 'Tue, 31 Jan 2023 18:55:13 GMT'</AuthenticationErrorDetail></Error>
[2023-01-31 12:55:14,438] {taskinstance.py:1395} INFO - Marking task as FAILED. dag_id=2.3_azure_storage_bigquery, task_id=transferir_azure, execution_date=20230130T000000, start_date=20230131T185513, end_date=20230131T185514
[2023-01-31 12:55:14,473] {standard_task_runner.py:92} ERROR - Failed to execute job 57 for task transferir_azure (Server failed to authenticate the request. Make sure the value of Authorization header is formed correctly including the signature.
RequestId:38725036-d01e-005b-13a8-3598c6000000
Time:2023-01-31T19:17:50.3508473Z
ErrorCode:AuthenticationFailed
authenticationerrordetail:Request date header too old: 'Tue, 31 Jan 2023 18:55:13 GMT'
Content: <?xml version="1.0" encoding="utf-8"?><Error><Code>AuthenticationFailed</Code><Message>Server failed to authenticate the request. Make sure the value of Authorization header is formed correctly including the signature.
RequestId:38725036-d01e-005b-13a8-3598c6000000
Time:2023-01-31T19:17:50.3508473Z</Message><AuthenticationErrorDetail>Request date header too old: 'Tue, 31 Jan 2023 18:55:13 GMT'</AuthenticationErrorDetail></Error>; 6802)
[2023-01-31 12:55:14,514] {local_task_job.py:156} INFO - Task exited with return code 1
[2023-01-31 12:55:14,597] {local_task_job.py:273} INFO - 0 downstream tasks scheduled from follow-on schedule check
