[2023-02-09 10:51:11,380] {taskinstance.py:1159} INFO - Dependencies all met for <TaskInstance: 7_dataproc_subdags.delete_cluster scheduled__2023-02-08T00:00:00+00:00 [queued]>
[2023-02-09 10:51:11,388] {taskinstance.py:1159} INFO - Dependencies all met for <TaskInstance: 7_dataproc_subdags.delete_cluster scheduled__2023-02-08T00:00:00+00:00 [queued]>
[2023-02-09 10:51:11,389] {taskinstance.py:1356} INFO - 
--------------------------------------------------------------------------------
[2023-02-09 10:51:11,390] {taskinstance.py:1357} INFO - Starting attempt 1 of 1
[2023-02-09 10:51:11,391] {taskinstance.py:1358} INFO - 
--------------------------------------------------------------------------------
[2023-02-09 10:51:11,400] {taskinstance.py:1377} INFO - Executing <Task(DataprocDeleteClusterOperator): delete_cluster> on 2023-02-08 00:00:00+00:00
[2023-02-09 10:51:11,403] {standard_task_runner.py:52} INFO - Started process 1411 to run task
[2023-02-09 10:51:11,406] {standard_task_runner.py:79} INFO - Running: ['***', 'tasks', 'run', '7_dataproc_subdags', 'delete_cluster', 'scheduled__2023-02-08T00:00:00+00:00', '--job-id', '8', '--raw', '--subdir', 'DAGS_FOLDER/Airflow2_0_De_0_a_Heroe/7_dataproc_subdags.py', '--cfg-path', '/tmp/tmpni12er2x', '--error-file', '/tmp/tmp3s10klch']
[2023-02-09 10:51:11,407] {standard_task_runner.py:80} INFO - Job 8: Subtask delete_cluster
[2023-02-09 10:51:11,469] {task_command.py:369} INFO - Running <TaskInstance: 7_dataproc_subdags.delete_cluster scheduled__2023-02-08T00:00:00+00:00 [running]> on host Tinmar.
[2023-02-09 10:51:11,533] {taskinstance.py:1569} INFO - Exporting the following env vars:
AIRFLOW_CTX_DAG_OWNER=David Sanchez
AIRFLOW_CTX_DAG_ID=7_dataproc_subdags
AIRFLOW_CTX_TASK_ID=delete_cluster
AIRFLOW_CTX_EXECUTION_DATE=2023-02-08T00:00:00+00:00
AIRFLOW_CTX_TRY_NUMBER=1
AIRFLOW_CTX_DAG_RUN_ID=scheduled__2023-02-08T00:00:00+00:00
[2023-02-09 10:51:11,546] {base.py:68} INFO - Using connection ID 'google_cloud_default' for task execution.
[2023-02-09 10:51:11,547] {dataproc.py:817} INFO - Deleting cluster: ***-spark-cluster
[2023-02-09 10:51:11,547] {credentials_provider.py:323} INFO - Getting connection using `google.auth.default()` since no key file is defined for hook.
[2023-02-09 10:51:14,551] {_metadata.py:99} WARNING - Compute Engine Metadata server unavailable on attempt 1 of 3. Reason: timed out
[2023-02-09 10:51:17,556] {_metadata.py:99} WARNING - Compute Engine Metadata server unavailable on attempt 2 of 3. Reason: timed out
[2023-02-09 10:51:20,560] {_metadata.py:99} WARNING - Compute Engine Metadata server unavailable on attempt 3 of 3. Reason: timed out
[2023-02-09 10:51:20,560] {_default.py:301} WARNING - Authentication failed using Compute Engine authentication due to unavailable metadata server.
[2023-02-09 10:51:20,560] {taskinstance.py:1889} ERROR - Task failed with exception
Traceback (most recent call last):
  File "/home/tinmar/.local/lib/python3.10/site-packages/airflow/providers/google/cloud/operators/dataproc.py", line 818, in execute
    operation = hook.delete_cluster(
  File "/home/tinmar/.local/lib/python3.10/site-packages/airflow/providers/google/common/hooks/base_google.py", line 462, in inner_wrapper
    return func(self, *args, **kwargs)
  File "/home/tinmar/.local/lib/python3.10/site-packages/airflow/providers/google/cloud/hooks/dataproc.py", line 364, in delete_cluster
    client = self.get_cluster_client(region=region)
  File "/home/tinmar/.local/lib/python3.10/site-packages/airflow/providers/google/cloud/hooks/dataproc.py", line 222, in get_cluster_client
    credentials=self.get_credentials(), client_info=CLIENT_INFO, client_options=client_options
  File "/home/tinmar/.local/lib/python3.10/site-packages/airflow/providers/google/common/hooks/base_google.py", line 275, in get_credentials
    credentials, _ = self.get_credentials_and_project_id()
  File "/home/tinmar/.local/lib/python3.10/site-packages/airflow/providers/google/common/hooks/base_google.py", line 253, in get_credentials_and_project_id
    credentials, project_id = get_credentials_and_project_id(
  File "/home/tinmar/.local/lib/python3.10/site-packages/airflow/providers/google/cloud/utils/credentials_provider.py", line 332, in get_credentials_and_project_id
    return _CredentialProvider(*args, **kwargs).get_credentials_and_project()
  File "/home/tinmar/.local/lib/python3.10/site-packages/airflow/providers/google/cloud/utils/credentials_provider.py", line 237, in get_credentials_and_project
    credentials, project_id = self._get_credentials_using_adc()
  File "/home/tinmar/.local/lib/python3.10/site-packages/airflow/providers/google/cloud/utils/credentials_provider.py", line 318, in _get_credentials_using_adc
    credentials, project_id = google.auth.default(scopes=self.scopes)
  File "/home/tinmar/.local/lib/python3.10/site-packages/google/auth/_default.py", line 653, in default
    raise exceptions.DefaultCredentialsError(_HELP_MESSAGE)
google.auth.exceptions.DefaultCredentialsError: Could not automatically determine credentials. Please set GOOGLE_APPLICATION_CREDENTIALS or explicitly create credentials and re-run the application. For more information, please see https://cloud.google.com/docs/authentication/getting-started
[2023-02-09 10:51:20,573] {taskinstance.py:1395} INFO - Marking task as FAILED. dag_id=7_dataproc_subdags, task_id=delete_cluster, execution_date=20230208T000000, start_date=20230209T165111, end_date=20230209T165120
[2023-02-09 10:51:20,583] {standard_task_runner.py:92} ERROR - Failed to execute job 8 for task delete_cluster (Could not automatically determine credentials. Please set GOOGLE_APPLICATION_CREDENTIALS or explicitly create credentials and re-run the application. For more information, please see https://cloud.google.com/docs/authentication/getting-started; 1411)
[2023-02-09 10:51:20,621] {local_task_job.py:156} INFO - Task exited with return code 1
[2023-02-09 10:51:20,656] {local_task_job.py:273} INFO - 0 downstream tasks scheduled from follow-on schedule check
