[2023-02-02 10:02:07,117] {taskinstance.py:1159} INFO - Dependencies all met for <TaskInstance: 6_dataproc_airflow.impar_task manual__2023-02-02T00:11:53.728323+00:00 [queued]>
[2023-02-02 10:02:07,133] {taskinstance.py:1159} INFO - Dependencies all met for <TaskInstance: 6_dataproc_airflow.impar_task manual__2023-02-02T00:11:53.728323+00:00 [queued]>
[2023-02-02 10:02:07,133] {taskinstance.py:1356} INFO - 
--------------------------------------------------------------------------------
[2023-02-02 10:02:07,134] {taskinstance.py:1357} INFO - Starting attempt 2 of 2
[2023-02-02 10:02:07,135] {taskinstance.py:1358} INFO - 
--------------------------------------------------------------------------------
[2023-02-02 10:02:07,165] {taskinstance.py:1377} INFO - Executing <Task(DataprocSubmitJobOperator): impar_task> on 2023-02-02 00:11:53.728323+00:00
[2023-02-02 10:02:07,166] {standard_task_runner.py:52} INFO - Started process 16761 to run task
[2023-02-02 10:02:07,168] {standard_task_runner.py:79} INFO - Running: ['airflow', 'tasks', 'run', '6_dataproc_airflow', 'impar_task', 'manual__2023-02-02T00:11:53.728323+00:00', '--job-id', '156', '--raw', '--subdir', 'DAGS_FOLDER/Airflow2_0_De_0_a_Heroe/6_dataproc_airflow.py', '--cfg-path', '/tmp/tmpep5__y0f', '--error-file', '/tmp/tmprwr38j4t']
[2023-02-02 10:02:07,170] {standard_task_runner.py:80} INFO - Job 156: Subtask impar_task
[2023-02-02 10:02:07,245] {task_command.py:369} INFO - Running <TaskInstance: 6_dataproc_airflow.impar_task manual__2023-02-02T00:11:53.728323+00:00 [running]> on host Tinmar.
[2023-02-02 10:02:07,357] {taskinstance.py:1569} INFO - Exporting the following env vars:
AIRFLOW_CTX_DAG_OWNER=David S
AIRFLOW_CTX_DAG_ID=6_dataproc_airflow
AIRFLOW_CTX_TASK_ID=impar_task
AIRFLOW_CTX_EXECUTION_DATE=2023-02-02T00:11:53.728323+00:00
AIRFLOW_CTX_TRY_NUMBER=2
AIRFLOW_CTX_DAG_RUN_ID=manual__2023-02-02T00:11:53.728323+00:00
[2023-02-02 10:02:07,358] {dataproc.py:1866} INFO - Submitting job
[2023-02-02 10:02:07,372] {base.py:68} INFO - Using connection ID 'google_cloud_default' for task execution.
[2023-02-02 10:02:07,992] {taskinstance.py:1889} ERROR - Task failed with exception
Traceback (most recent call last):
  File "/home/tinmar/.local/lib/python3.10/site-packages/google/api_core/grpc_helpers.py", line 50, in error_remapped_callable
    return callable_(*args, **kwargs)
  File "/home/tinmar/.local/lib/python3.10/site-packages/grpc/_channel.py", line 946, in __call__
    return _end_unary_response_blocking(state, call, False, None)
  File "/home/tinmar/.local/lib/python3.10/site-packages/grpc/_channel.py", line 849, in _end_unary_response_blocking
    raise _InactiveRpcError(state)
grpc._channel._InactiveRpcError: <_InactiveRpcError of RPC that terminated with:
	status = StatusCode.ALREADY_EXISTS
	details = "Already exists: Failed to submit job: Job projects/serene-gradient-371719/regions/us-central1/jobs/IMPARTASK_dfa22fbf"
	debug_error_string = "UNKNOWN:Error received from peer ipv4:142.251.34.10:443 {created_time:"2023-02-02T10:02:07.991700993-06:00", grpc_status:6, grpc_message:"Already exists: Failed to submit job: Job projects/serene-gradient-371719/regions/us-central1/jobs/IMPARTASK_dfa22fbf"}"
>

The above exception was the direct cause of the following exception:

Traceback (most recent call last):
  File "/home/tinmar/.local/lib/python3.10/site-packages/airflow/providers/google/cloud/operators/dataproc.py", line 1868, in execute
    job_object = self.hook.submit_job(
  File "/home/tinmar/.local/lib/python3.10/site-packages/airflow/providers/google/common/hooks/base_google.py", line 462, in inner_wrapper
    return func(self, *args, **kwargs)
  File "/home/tinmar/.local/lib/python3.10/site-packages/airflow/providers/google/cloud/hooks/dataproc.py", line 780, in submit_job
    return client.submit_job(
  File "/home/tinmar/.local/lib/python3.10/site-packages/google/cloud/dataproc_v1/services/job_controller/client.py", line 520, in submit_job
    response = rpc(
  File "/home/tinmar/.local/lib/python3.10/site-packages/google/api_core/gapic_v1/method.py", line 154, in __call__
    return wrapped_func(*args, **kwargs)
  File "/home/tinmar/.local/lib/python3.10/site-packages/google/api_core/retry.py", line 283, in retry_wrapped_func
    return retry_target(
  File "/home/tinmar/.local/lib/python3.10/site-packages/google/api_core/retry.py", line 190, in retry_target
    return target()
  File "/home/tinmar/.local/lib/python3.10/site-packages/google/api_core/grpc_helpers.py", line 52, in error_remapped_callable
    raise exceptions.from_grpc_error(exc) from exc
google.api_core.exceptions.AlreadyExists: 409 Already exists: Failed to submit job: Job projects/serene-gradient-371719/regions/us-central1/jobs/IMPARTASK_dfa22fbf
[2023-02-02 10:02:08,019] {taskinstance.py:1395} INFO - Marking task as FAILED. dag_id=6_dataproc_airflow, task_id=impar_task, execution_date=20230202T001153, start_date=20230202T160207, end_date=20230202T160208
[2023-02-02 10:02:08,068] {standard_task_runner.py:92} ERROR - Failed to execute job 156 for task impar_task (409 Already exists: Failed to submit job: Job projects/serene-gradient-371719/regions/us-central1/jobs/IMPARTASK_dfa22fbf; 16761)
[2023-02-02 10:02:08,088] {local_task_job.py:156} INFO - Task exited with return code 1
