[2023-02-09 10:53:08,369] {taskinstance.py:1159} INFO - Dependencies all met for <TaskInstance: 7_dataproc_subdags.delete_cluster manual__2023-02-09T16:42:00.190347+00:00 [queued]>
[2023-02-09 10:53:08,377] {taskinstance.py:1159} INFO - Dependencies all met for <TaskInstance: 7_dataproc_subdags.delete_cluster manual__2023-02-09T16:42:00.190347+00:00 [queued]>
[2023-02-09 10:53:08,378] {taskinstance.py:1356} INFO - 
--------------------------------------------------------------------------------
[2023-02-09 10:53:08,379] {taskinstance.py:1357} INFO - Starting attempt 2 of 2
[2023-02-09 10:53:08,379] {taskinstance.py:1358} INFO - 
--------------------------------------------------------------------------------
[2023-02-09 10:53:08,388] {taskinstance.py:1377} INFO - Executing <Task(DataprocDeleteClusterOperator): delete_cluster> on 2023-02-09 16:42:00.190347+00:00
[2023-02-09 10:53:08,390] {standard_task_runner.py:52} INFO - Started process 2383 to run task
[2023-02-09 10:53:08,394] {standard_task_runner.py:79} INFO - Running: ['***', 'tasks', 'run', '7_dataproc_subdags', 'delete_cluster', 'manual__2023-02-09T16:42:00.190347+00:00', '--job-id', '10', '--raw', '--subdir', 'DAGS_FOLDER/Airflow2_0_De_0_a_Heroe/7_dataproc_subdags.py', '--cfg-path', '/tmp/tmp9m9ftzds', '--error-file', '/tmp/tmprhxk_wrd']
[2023-02-09 10:53:08,396] {standard_task_runner.py:80} INFO - Job 10: Subtask delete_cluster
[2023-02-09 10:53:08,458] {task_command.py:369} INFO - Running <TaskInstance: 7_dataproc_subdags.delete_cluster manual__2023-02-09T16:42:00.190347+00:00 [running]> on host Tinmar.
[2023-02-09 10:53:08,525] {taskinstance.py:1569} INFO - Exporting the following env vars:
AIRFLOW_CTX_DAG_OWNER=David Sanchez
AIRFLOW_CTX_DAG_ID=7_dataproc_subdags
AIRFLOW_CTX_TASK_ID=delete_cluster
AIRFLOW_CTX_EXECUTION_DATE=2023-02-09T16:42:00.190347+00:00
AIRFLOW_CTX_TRY_NUMBER=2
AIRFLOW_CTX_DAG_RUN_ID=manual__2023-02-09T16:42:00.190347+00:00
[2023-02-09 10:53:08,541] {base.py:68} INFO - Using connection ID 'google_cloud_default' for task execution.
[2023-02-09 10:53:08,542] {dataproc.py:817} INFO - Deleting cluster: ***-spark-cluster
[2023-02-09 10:53:08,543] {taskinstance.py:1889} ERROR - Task failed with exception
Traceback (most recent call last):
  File "/home/tinmar/.local/lib/python3.10/site-packages/airflow/providers/google/cloud/operators/dataproc.py", line 818, in execute
    operation = hook.delete_cluster(
  File "/home/tinmar/.local/lib/python3.10/site-packages/airflow/providers/google/common/hooks/base_google.py", line 462, in inner_wrapper
    return func(self, *args, **kwargs)
  File "/home/tinmar/.local/lib/python3.10/site-packages/airflow/providers/google/cloud/hooks/dataproc.py", line 364, in delete_cluster
    client = self.get_cluster_client(region=region)
  File "/home/tinmar/.local/lib/python3.10/site-packages/airflow/providers/google/cloud/hooks/dataproc.py", line 222, in get_cluster_client
    credentials=self.get_credentials(), client_info=CLIENT_INFO, client_options=client_options
  File "/home/tinmar/.local/lib/python3.10/site-packages/airflow/providers/google/common/hooks/base_google.py", line 275, in get_credentials
    credentials, _ = self.get_credentials_and_project_id()
  File "/home/tinmar/.local/lib/python3.10/site-packages/airflow/providers/google/common/hooks/base_google.py", line 253, in get_credentials_and_project_id
    credentials, project_id = get_credentials_and_project_id(
  File "/home/tinmar/.local/lib/python3.10/site-packages/airflow/providers/google/cloud/utils/credentials_provider.py", line 332, in get_credentials_and_project_id
    return _CredentialProvider(*args, **kwargs).get_credentials_and_project()
  File "/home/tinmar/.local/lib/python3.10/site-packages/airflow/providers/google/cloud/utils/credentials_provider.py", line 231, in get_credentials_and_project
    credentials, project_id = self._get_credentials_using_key_path()
  File "/home/tinmar/.local/lib/python3.10/site-packages/airflow/providers/google/cloud/utils/credentials_provider.py", line 280, in _get_credentials_using_key_path
    credentials = google.oauth2.service_account.Credentials.from_service_account_file(
  File "/home/tinmar/.local/lib/python3.10/site-packages/google/oauth2/service_account.py", line 241, in from_service_account_file
    info, signer = _service_account_info.from_filename(
  File "/home/tinmar/.local/lib/python3.10/site-packages/google/auth/_service_account_info.py", line 80, in from_filename
    with io.open(filename, "r", encoding="utf-8") as json_file:
FileNotFoundError: [Errno 2] No such file or directory: 'C:\\Users\\tinma\\OneDrive\\Escritorio\\keys_IAM\\testing_key_gcp.json'
[2023-02-09 10:53:08,558] {taskinstance.py:1395} INFO - Marking task as FAILED. dag_id=7_dataproc_subdags, task_id=delete_cluster, execution_date=20230209T164200, start_date=20230209T165308, end_date=20230209T165308
[2023-02-09 10:53:08,567] {standard_task_runner.py:92} ERROR - Failed to execute job 10 for task delete_cluster ([Errno 2] No such file or directory: 'C:\\Users\\tinma\\OneDrive\\Escritorio\\keys_IAM\\testing_key_gcp.json'; 2383)
[2023-02-09 10:53:08,610] {local_task_job.py:156} INFO - Task exited with return code 1
[2023-02-09 10:53:08,650] {local_task_job.py:273} INFO - 0 downstream tasks scheduled from follow-on schedule check
