[2023-02-13 11:22:54,539] {taskinstance.py:1159} INFO - Dependencies all met for <TaskInstance: xcoms_cuarto_dag.xcom_pull manual__2023-02-13T17:22:52.360192+00:00 [queued]>
[2023-02-13 11:22:54,544] {taskinstance.py:1159} INFO - Dependencies all met for <TaskInstance: xcoms_cuarto_dag.xcom_pull manual__2023-02-13T17:22:52.360192+00:00 [queued]>
[2023-02-13 11:22:54,545] {taskinstance.py:1356} INFO - 
--------------------------------------------------------------------------------
[2023-02-13 11:22:54,546] {taskinstance.py:1357} INFO - Starting attempt 1 of 1
[2023-02-13 11:22:54,546] {taskinstance.py:1358} INFO - 
--------------------------------------------------------------------------------
[2023-02-13 11:22:54,553] {taskinstance.py:1377} INFO - Executing <Task(PythonOperator): xcom_pull> on 2023-02-13 17:22:52.360192+00:00
[2023-02-13 11:22:54,556] {standard_task_runner.py:52} INFO - Started process 77648 to run task
[2023-02-13 11:22:54,557] {standard_task_runner.py:79} INFO - Running: ['***', 'tasks', 'run', 'xcoms_cuarto_dag', 'xcom_pull', 'manual__2023-02-13T17:22:52.360192+00:00', '--job-id', '108', '--raw', '--subdir', 'DAGS_FOLDER/Apache_Airflow/xcoms_cuarto_dag.py', '--cfg-path', '/tmp/tmplej5fjr9', '--error-file', '/tmp/tmpbah7cwu6']
[2023-02-13 11:22:54,559] {standard_task_runner.py:80} INFO - Job 108: Subtask xcom_pull
[2023-02-13 11:22:54,597] {task_command.py:369} INFO - Running <TaskInstance: xcoms_cuarto_dag.xcom_pull manual__2023-02-13T17:22:52.360192+00:00 [running]> on host Tinmar.
[2023-02-13 11:22:54,644] {taskinstance.py:1569} INFO - Exporting the following env vars:
AIRFLOW_CTX_DAG_OWNER=Tinmar
AIRFLOW_CTX_DAG_ID=xcoms_cuarto_dag
AIRFLOW_CTX_TASK_ID=xcom_pull
AIRFLOW_CTX_EXECUTION_DATE=2023-02-13T17:22:52.360192+00:00
AIRFLOW_CTX_TRY_NUMBER=1
AIRFLOW_CTX_DAG_RUN_ID=manual__2023-02-13T17:22:52.360192+00:00
[2023-02-13 11:22:54,645] {taskinstance.py:1889} ERROR - Task failed with exception
Traceback (most recent call last):
  File "/home/tinmar/.local/lib/python3.10/site-packages/airflow/operators/python.py", line 171, in execute
    return_value = self.execute_callable()
  File "/home/tinmar/.local/lib/python3.10/site-packages/airflow/operators/python.py", line 189, in execute_callable
    return self.python_callable(*self.op_args, **self.op_kwargs)
TypeError: xcom_pull() takes 0 positional arguments but 8 were given
[2023-02-13 11:22:54,654] {taskinstance.py:1395} INFO - Marking task as FAILED. dag_id=xcoms_cuarto_dag, task_id=xcom_pull, execution_date=20230213T172252, start_date=20230213T172254, end_date=20230213T172254
[2023-02-13 11:22:54,661] {standard_task_runner.py:92} ERROR - Failed to execute job 108 for task xcom_pull (xcom_pull() takes 0 positional arguments but 8 were given; 77648)
[2023-02-13 11:22:54,695] {local_task_job.py:156} INFO - Task exited with return code 1
[2023-02-13 11:22:54,724] {local_task_job.py:273} INFO - 0 downstream tasks scheduled from follow-on schedule check
