[2023-02-09 11:04:29,995] {taskinstance.py:1159} INFO - Dependencies all met for <TaskInstance: 7_dataproc_subdags.delete_cluster manual__2023-02-09T16:42:00.190347+00:00 [queued]>
[2023-02-09 11:04:30,002] {taskinstance.py:1159} INFO - Dependencies all met for <TaskInstance: 7_dataproc_subdags.delete_cluster manual__2023-02-09T16:42:00.190347+00:00 [queued]>
[2023-02-09 11:04:30,005] {taskinstance.py:1356} INFO - 
--------------------------------------------------------------------------------
[2023-02-09 11:04:30,008] {taskinstance.py:1357} INFO - Starting attempt 7 of 7
[2023-02-09 11:04:30,008] {taskinstance.py:1358} INFO - 
--------------------------------------------------------------------------------
[2023-02-09 11:04:30,019] {taskinstance.py:1377} INFO - Executing <Task(DataprocDeleteClusterOperator): delete_cluster> on 2023-02-09 16:42:00.190347+00:00
[2023-02-09 11:04:30,022] {standard_task_runner.py:52} INFO - Started process 9390 to run task
[2023-02-09 11:04:30,027] {standard_task_runner.py:79} INFO - Running: ['***', 'tasks', 'run', '7_dataproc_subdags', 'delete_cluster', 'manual__2023-02-09T16:42:00.190347+00:00', '--job-id', '20', '--raw', '--subdir', 'DAGS_FOLDER/Airflow2_0_De_0_a_Heroe/7_dataproc_subdags.py', '--cfg-path', '/tmp/tmplitcphn9', '--error-file', '/tmp/tmpc1x6vhdd']
[2023-02-09 11:04:30,028] {standard_task_runner.py:80} INFO - Job 20: Subtask delete_cluster
[2023-02-09 11:04:30,100] {task_command.py:369} INFO - Running <TaskInstance: 7_dataproc_subdags.delete_cluster manual__2023-02-09T16:42:00.190347+00:00 [running]> on host Tinmar.
[2023-02-09 11:04:30,168] {taskinstance.py:1569} INFO - Exporting the following env vars:
AIRFLOW_CTX_DAG_OWNER=David Sanchez
AIRFLOW_CTX_DAG_ID=7_dataproc_subdags
AIRFLOW_CTX_TASK_ID=delete_cluster
AIRFLOW_CTX_EXECUTION_DATE=2023-02-09T16:42:00.190347+00:00
AIRFLOW_CTX_TRY_NUMBER=7
AIRFLOW_CTX_DAG_RUN_ID=manual__2023-02-09T16:42:00.190347+00:00
[2023-02-09 11:04:30,183] {base.py:68} INFO - Using connection ID 'google_cloud_default' for task execution.
[2023-02-09 11:04:30,185] {dataproc.py:817} INFO - Deleting cluster: ***-spark-cluster
[2023-02-09 11:04:30,202] {taskinstance.py:1889} ERROR - Task failed with exception
Traceback (most recent call last):
  File "/home/tinmar/.local/lib/python3.10/site-packages/airflow/providers/google/common/hooks/base_google.py", line 245, in get_credentials_and_project_id
    keyfile_dict_json = json.loads(keyfile_dict)
  File "/usr/lib/python3.10/json/__init__.py", line 346, in loads
    return _default_decoder.decode(s)
  File "/usr/lib/python3.10/json/decoder.py", line 337, in decode
    obj, end = self.raw_decode(s, idx=_w(s, 0).end())
  File "/usr/lib/python3.10/json/decoder.py", line 355, in raw_decode
    raise JSONDecodeError("Expecting value", s, err.value) from None
json.decoder.JSONDecodeError: Expecting value: line 1 column 1 (char 0)

During handling of the above exception, another exception occurred:

Traceback (most recent call last):
  File "/home/tinmar/.local/lib/python3.10/site-packages/airflow/providers/google/cloud/operators/dataproc.py", line 818, in execute
    operation = hook.delete_cluster(
  File "/home/tinmar/.local/lib/python3.10/site-packages/airflow/providers/google/common/hooks/base_google.py", line 462, in inner_wrapper
    return func(self, *args, **kwargs)
  File "/home/tinmar/.local/lib/python3.10/site-packages/airflow/providers/google/cloud/hooks/dataproc.py", line 364, in delete_cluster
    client = self.get_cluster_client(region=region)
  File "/home/tinmar/.local/lib/python3.10/site-packages/airflow/providers/google/cloud/hooks/dataproc.py", line 222, in get_cluster_client
    credentials=self.get_credentials(), client_info=CLIENT_INFO, client_options=client_options
  File "/home/tinmar/.local/lib/python3.10/site-packages/airflow/providers/google/common/hooks/base_google.py", line 275, in get_credentials
    credentials, _ = self.get_credentials_and_project_id()
  File "/home/tinmar/.local/lib/python3.10/site-packages/airflow/providers/google/common/hooks/base_google.py", line 247, in get_credentials_and_project_id
    raise AirflowException("Invalid key JSON.")
airflow.exceptions.AirflowException: Invalid key JSON.
[2023-02-09 11:04:30,207] {taskinstance.py:1395} INFO - Marking task as FAILED. dag_id=7_dataproc_subdags, task_id=delete_cluster, execution_date=20230209T164200, start_date=20230209T170429, end_date=20230209T170430
[2023-02-09 11:04:30,216] {standard_task_runner.py:92} ERROR - Failed to execute job 20 for task delete_cluster (Invalid key JSON.; 9390)
[2023-02-09 11:04:30,245] {local_task_job.py:156} INFO - Task exited with return code 1
[2023-02-09 11:04:30,280] {local_task_job.py:273} INFO - 0 downstream tasks scheduled from follow-on schedule check
