[2023-02-20T09:18:28.544-0600] {taskinstance.py:1165} INFO - Dependencies all met for <TaskInstance: 7_dataproc_subdags.delete_cluster scheduled__2023-02-18T00:00:00+00:00 [queued]>
[2023-02-20T09:18:28.559-0600] {taskinstance.py:1165} INFO - Dependencies all met for <TaskInstance: 7_dataproc_subdags.delete_cluster scheduled__2023-02-18T00:00:00+00:00 [queued]>
[2023-02-20T09:18:28.560-0600] {taskinstance.py:1362} INFO - 
--------------------------------------------------------------------------------
[2023-02-20T09:18:28.561-0600] {taskinstance.py:1363} INFO - Starting attempt 1 of 1
[2023-02-20T09:18:28.562-0600] {taskinstance.py:1364} INFO - 
--------------------------------------------------------------------------------
[2023-02-20T09:18:28.579-0600] {taskinstance.py:1383} INFO - Executing <Task(DataprocDeleteClusterOperator): delete_cluster> on 2023-02-18 00:00:00+00:00
[2023-02-20T09:18:28.585-0600] {standard_task_runner.py:54} INFO - Started process 198249 to run task
[2023-02-20T09:18:28.589-0600] {standard_task_runner.py:82} INFO - Running: ['***', 'tasks', 'run', '7_dataproc_subdags', 'delete_cluster', 'scheduled__2023-02-18T00:00:00+00:00', '--job-id', '559', '--raw', '--subdir', 'DAGS_FOLDER/Airflow2_0_De_0_a_Heroe/7_dataproc_subdags.py', '--cfg-path', '/tmp/tmpvny7t52r']
[2023-02-20T09:18:28.614-0600] {standard_task_runner.py:83} INFO - Job 559: Subtask delete_cluster
[2023-02-20T09:18:28.671-0600] {dagbag.py:525} INFO - Filling up the DagBag from /c/Airflow/dags/Airflow2_0_De_0_a_Heroe/7_dataproc_subdags.py
[2023-02-20T09:18:28.926-0600] {logging_mixin.py:117} WARNING - /home/tinmar/.local/lib/python3.10/site-packages/***/models/baseoperator.py:408 DeprecationWarning: Passing cluster parameters by keywords to `DataprocCreateClusterOperator` will be deprecated. Please provide cluster_config object using `cluster_config` parameter. You can use `***.dataproc.ClusterGenerator.generate_cluster` method to obtain cluster object.
[2023-02-20T09:18:29.047-0600] {task_command.py:384} INFO - Running <TaskInstance: 7_dataproc_subdags.delete_cluster scheduled__2023-02-18T00:00:00+00:00 [running]> on host Tinmar.
[2023-02-20T09:18:29.120-0600] {taskinstance.py:1590} INFO - Exporting the following env vars:
AIRFLOW_CTX_DAG_OWNER=David Sanchez
AIRFLOW_CTX_DAG_ID=7_dataproc_subdags
AIRFLOW_CTX_TASK_ID=delete_cluster
AIRFLOW_CTX_EXECUTION_DATE=2023-02-18T00:00:00+00:00
AIRFLOW_CTX_TRY_NUMBER=1
AIRFLOW_CTX_DAG_RUN_ID=scheduled__2023-02-18T00:00:00+00:00
[2023-02-20T09:18:29.140-0600] {base.py:71} INFO - Using connection ID 'google_cloud_default' for task execution.
[2023-02-20T09:18:29.148-0600] {dataproc.py:817} INFO - Deleting cluster: ***-spark-cluster
[2023-02-20T09:18:35.622-0600] {taskinstance.py:1851} ERROR - Task failed with exception
Traceback (most recent call last):
  File "/home/tinmar/.local/lib/python3.10/site-packages/google/api_core/grpc_helpers.py", line 50, in error_remapped_callable
    return callable_(*args, **kwargs)
  File "/home/tinmar/.local/lib/python3.10/site-packages/grpc/_channel.py", line 946, in __call__
    return _end_unary_response_blocking(state, call, False, None)
  File "/home/tinmar/.local/lib/python3.10/site-packages/grpc/_channel.py", line 849, in _end_unary_response_blocking
    raise _InactiveRpcError(state)
grpc._channel._InactiveRpcError: <_InactiveRpcError of RPC that terminated with:
	status = StatusCode.NOT_FOUND
	details = "Not found: Cluster projects/serene-gradient-371719/regions/us-central1/clusters/airflow-spark-cluster"
	debug_error_string = "UNKNOWN:Error received from peer ipv4:216.58.195.234:443 {created_time:"2023-02-20T09:18:35.621124844-06:00", grpc_status:5, grpc_message:"Not found: Cluster projects/serene-gradient-371719/regions/us-central1/clusters/airflow-spark-cluster"}"
>

The above exception was the direct cause of the following exception:

Traceback (most recent call last):
  File "/home/tinmar/.local/lib/python3.10/site-packages/airflow/providers/google/cloud/operators/dataproc.py", line 818, in execute
    operation = hook.delete_cluster(
  File "/home/tinmar/.local/lib/python3.10/site-packages/airflow/providers/google/common/hooks/base_google.py", line 462, in inner_wrapper
    return func(self, *args, **kwargs)
  File "/home/tinmar/.local/lib/python3.10/site-packages/airflow/providers/google/cloud/hooks/dataproc.py", line 365, in delete_cluster
    result = client.delete_cluster(
  File "/home/tinmar/.local/lib/python3.10/site-packages/google/cloud/dataproc_v1/services/cluster_controller/client.py", line 1124, in delete_cluster
    response = rpc(
  File "/home/tinmar/.local/lib/python3.10/site-packages/google/api_core/gapic_v1/method.py", line 154, in __call__
    return wrapped_func(*args, **kwargs)
  File "/home/tinmar/.local/lib/python3.10/site-packages/google/api_core/retry.py", line 283, in retry_wrapped_func
    return retry_target(
  File "/home/tinmar/.local/lib/python3.10/site-packages/google/api_core/retry.py", line 190, in retry_target
    return target()
  File "/home/tinmar/.local/lib/python3.10/site-packages/google/api_core/grpc_helpers.py", line 52, in error_remapped_callable
    raise exceptions.from_grpc_error(exc) from exc
google.api_core.exceptions.NotFound: 404 Not found: Cluster projects/serene-gradient-371719/regions/us-central1/clusters/airflow-spark-cluster
[2023-02-20T09:18:35.638-0600] {taskinstance.py:1401} INFO - Marking task as FAILED. dag_id=7_dataproc_subdags, task_id=delete_cluster, execution_date=20230218T000000, start_date=20230220T151828, end_date=20230220T151835
[2023-02-20T09:18:35.666-0600] {standard_task_runner.py:102} ERROR - Failed to execute job 559 for task delete_cluster (404 Not found: Cluster projects/serene-gradient-371719/regions/us-central1/clusters/airflow-spark-cluster; 198249)
[2023-02-20T09:18:35.716-0600] {local_task_job.py:164} INFO - Task exited with return code 1
[2023-02-20T09:18:35.828-0600] {local_task_job.py:273} INFO - 0 downstream tasks scheduled from follow-on schedule check
