[2023-02-01 17:45:45,225] {taskinstance.py:1159} INFO - Dependencies all met for <TaskInstance: 6_dataproc_airflow.delete_cluster scheduled__2023-01-31T00:00:00+00:00 [queued]>
[2023-02-01 17:45:45,239] {taskinstance.py:1159} INFO - Dependencies all met for <TaskInstance: 6_dataproc_airflow.delete_cluster scheduled__2023-01-31T00:00:00+00:00 [queued]>
[2023-02-01 17:45:45,239] {taskinstance.py:1356} INFO - 
--------------------------------------------------------------------------------
[2023-02-01 17:45:45,241] {taskinstance.py:1357} INFO - Starting attempt 6 of 6
[2023-02-01 17:45:45,242] {taskinstance.py:1358} INFO - 
--------------------------------------------------------------------------------
[2023-02-01 17:45:45,273] {taskinstance.py:1377} INFO - Executing <Task(DataprocDeleteClusterOperator): delete_cluster> on 2023-01-31 00:00:00+00:00
[2023-02-01 17:45:45,274] {standard_task_runner.py:52} INFO - Started process 13771 to run task
[2023-02-01 17:45:45,276] {standard_task_runner.py:79} INFO - Running: ['airflow', 'tasks', 'run', '6_dataproc_airflow', 'delete_cluster', 'scheduled__2023-01-31T00:00:00+00:00', '--job-id', '131', '--raw', '--subdir', 'DAGS_FOLDER/Airflow2_0_De_0_a_Heroe/6_dataproc_airflow.py', '--cfg-path', '/tmp/tmp8u4_l63w', '--error-file', '/tmp/tmpstc7_x65']
[2023-02-01 17:45:45,278] {standard_task_runner.py:80} INFO - Job 131: Subtask delete_cluster
[2023-02-01 17:45:45,342] {task_command.py:369} INFO - Running <TaskInstance: 6_dataproc_airflow.delete_cluster scheduled__2023-01-31T00:00:00+00:00 [running]> on host Tinmar.
[2023-02-01 17:45:45,439] {taskinstance.py:1569} INFO - Exporting the following env vars:
AIRFLOW_CTX_DAG_OWNER=David S
AIRFLOW_CTX_DAG_ID=6_dataproc_airflow
AIRFLOW_CTX_TASK_ID=delete_cluster
AIRFLOW_CTX_EXECUTION_DATE=2023-01-31T00:00:00+00:00
AIRFLOW_CTX_TRY_NUMBER=6
AIRFLOW_CTX_DAG_RUN_ID=scheduled__2023-01-31T00:00:00+00:00
[2023-02-01 17:45:45,451] {base.py:68} INFO - Using connection ID 'google_cloud_default' for task execution.
[2023-02-01 17:45:45,452] {dataproc.py:817} INFO - Deleting cluster: airflow-spark-cluster
[2023-02-01 17:45:46,221] {taskinstance.py:1889} ERROR - Task failed with exception
Traceback (most recent call last):
  File "/home/tinmar/.local/lib/python3.10/site-packages/google/api_core/grpc_helpers.py", line 50, in error_remapped_callable
    return callable_(*args, **kwargs)
  File "/home/tinmar/.local/lib/python3.10/site-packages/grpc/_channel.py", line 946, in __call__
    return _end_unary_response_blocking(state, call, False, None)
  File "/home/tinmar/.local/lib/python3.10/site-packages/grpc/_channel.py", line 849, in _end_unary_response_blocking
    raise _InactiveRpcError(state)
grpc._channel._InactiveRpcError: <_InactiveRpcError of RPC that terminated with:
	status = StatusCode.NOT_FOUND
	details = "Not found: Cluster projects/serene-gradient-371719/regions/us-central1/clusters/airflow-spark-cluster"
	debug_error_string = "UNKNOWN:Error received from peer ipv4:142.250.65.138:443 {created_time:"2023-02-01T17:45:46.221243142-06:00", grpc_status:5, grpc_message:"Not found: Cluster projects/serene-gradient-371719/regions/us-central1/clusters/airflow-spark-cluster"}"
>

The above exception was the direct cause of the following exception:

Traceback (most recent call last):
  File "/home/tinmar/.local/lib/python3.10/site-packages/airflow/providers/google/cloud/operators/dataproc.py", line 818, in execute
    operation = hook.delete_cluster(
  File "/home/tinmar/.local/lib/python3.10/site-packages/airflow/providers/google/common/hooks/base_google.py", line 462, in inner_wrapper
    return func(self, *args, **kwargs)
  File "/home/tinmar/.local/lib/python3.10/site-packages/airflow/providers/google/cloud/hooks/dataproc.py", line 365, in delete_cluster
    result = client.delete_cluster(
  File "/home/tinmar/.local/lib/python3.10/site-packages/google/cloud/dataproc_v1/services/cluster_controller/client.py", line 1124, in delete_cluster
    response = rpc(
  File "/home/tinmar/.local/lib/python3.10/site-packages/google/api_core/gapic_v1/method.py", line 154, in __call__
    return wrapped_func(*args, **kwargs)
  File "/home/tinmar/.local/lib/python3.10/site-packages/google/api_core/retry.py", line 283, in retry_wrapped_func
    return retry_target(
  File "/home/tinmar/.local/lib/python3.10/site-packages/google/api_core/retry.py", line 190, in retry_target
    return target()
  File "/home/tinmar/.local/lib/python3.10/site-packages/google/api_core/grpc_helpers.py", line 52, in error_remapped_callable
    raise exceptions.from_grpc_error(exc) from exc
google.api_core.exceptions.NotFound: 404 Not found: Cluster projects/serene-gradient-371719/regions/us-central1/clusters/airflow-spark-cluster
[2023-02-01 17:45:46,236] {taskinstance.py:1395} INFO - Marking task as FAILED. dag_id=6_dataproc_airflow, task_id=delete_cluster, execution_date=20230131T000000, start_date=20230201T234545, end_date=20230201T234546
[2023-02-01 17:45:46,270] {standard_task_runner.py:92} ERROR - Failed to execute job 131 for task delete_cluster (404 Not found: Cluster projects/serene-gradient-371719/regions/us-central1/clusters/airflow-spark-cluster; 13771)
[2023-02-01 17:45:46,294] {local_task_job.py:156} INFO - Task exited with return code 1
