[2023-02-09 10:59:50,354] {taskinstance.py:1159} INFO - Dependencies all met for <TaskInstance: 7_dataproc_subdags.create_cluster manual__2023-02-09T16:42:00.190347+00:00 [queued]>
[2023-02-09 10:59:50,363] {taskinstance.py:1159} INFO - Dependencies all met for <TaskInstance: 7_dataproc_subdags.create_cluster manual__2023-02-09T16:42:00.190347+00:00 [queued]>
[2023-02-09 10:59:50,364] {taskinstance.py:1356} INFO - 
--------------------------------------------------------------------------------
[2023-02-09 10:59:50,367] {taskinstance.py:1357} INFO - Starting attempt 5 of 5
[2023-02-09 10:59:50,368] {taskinstance.py:1358} INFO - 
--------------------------------------------------------------------------------
[2023-02-09 10:59:50,381] {taskinstance.py:1377} INFO - Executing <Task(DataprocCreateClusterOperator): create_cluster> on 2023-02-09 16:42:00.190347+00:00
[2023-02-09 10:59:50,389] {standard_task_runner.py:52} INFO - Started process 6647 to run task
[2023-02-09 10:59:50,391] {standard_task_runner.py:79} INFO - Running: ['***', 'tasks', 'run', '7_dataproc_subdags', 'create_cluster', 'manual__2023-02-09T16:42:00.190347+00:00', '--job-id', '15', '--raw', '--subdir', 'DAGS_FOLDER/Airflow2_0_De_0_a_Heroe/7_dataproc_subdags.py', '--cfg-path', '/tmp/tmp_ht19zs8', '--error-file', '/tmp/tmpke7ec61c']
[2023-02-09 10:59:50,394] {standard_task_runner.py:80} INFO - Job 15: Subtask create_cluster
[2023-02-09 10:59:50,475] {task_command.py:369} INFO - Running <TaskInstance: 7_dataproc_subdags.create_cluster manual__2023-02-09T16:42:00.190347+00:00 [running]> on host Tinmar.
[2023-02-09 10:59:50,568] {taskinstance.py:1569} INFO - Exporting the following env vars:
AIRFLOW_CTX_DAG_OWNER=David Sanchez
AIRFLOW_CTX_DAG_ID=7_dataproc_subdags
AIRFLOW_CTX_TASK_ID=create_cluster
AIRFLOW_CTX_EXECUTION_DATE=2023-02-09T16:42:00.190347+00:00
AIRFLOW_CTX_TRY_NUMBER=5
AIRFLOW_CTX_DAG_RUN_ID=manual__2023-02-09T16:42:00.190347+00:00
[2023-02-09 10:59:50,569] {dataproc.py:591} INFO - Creating cluster: ***-spark-cluster
[2023-02-09 10:59:50,590] {base.py:68} INFO - Using connection ID 'google_cloud_default' for task execution.
[2023-02-09 10:59:50,632] {taskinstance.py:1889} ERROR - Task failed with exception
Traceback (most recent call last):
  File "/home/tinmar/.local/lib/python3.10/site-packages/airflow/providers/google/common/hooks/base_google.py", line 245, in get_credentials_and_project_id
    keyfile_dict_json = json.loads(keyfile_dict)
  File "/usr/lib/python3.10/json/__init__.py", line 346, in loads
    return _default_decoder.decode(s)
  File "/usr/lib/python3.10/json/decoder.py", line 337, in decode
    obj, end = self.raw_decode(s, idx=_w(s, 0).end())
  File "/usr/lib/python3.10/json/decoder.py", line 355, in raw_decode
    raise JSONDecodeError("Expecting value", s, err.value) from None
json.decoder.JSONDecodeError: Expecting value: line 1 column 1 (char 0)

During handling of the above exception, another exception occurred:

Traceback (most recent call last):
  File "/home/tinmar/.local/lib/python3.10/site-packages/airflow/providers/google/cloud/operators/dataproc.py", line 599, in execute
    cluster = self._create_cluster(hook)
  File "/home/tinmar/.local/lib/python3.10/site-packages/airflow/providers/google/cloud/operators/dataproc.py", line 522, in _create_cluster
    operation = hook.create_cluster(
  File "/home/tinmar/.local/lib/python3.10/site-packages/airflow/providers/google/common/hooks/base_google.py", line 462, in inner_wrapper
    return func(self, *args, **kwargs)
  File "/home/tinmar/.local/lib/python3.10/site-packages/airflow/providers/google/cloud/hooks/dataproc.py", line 321, in create_cluster
    client = self.get_cluster_client(region=region)
  File "/home/tinmar/.local/lib/python3.10/site-packages/airflow/providers/google/cloud/hooks/dataproc.py", line 222, in get_cluster_client
    credentials=self.get_credentials(), client_info=CLIENT_INFO, client_options=client_options
  File "/home/tinmar/.local/lib/python3.10/site-packages/airflow/providers/google/common/hooks/base_google.py", line 275, in get_credentials
    credentials, _ = self.get_credentials_and_project_id()
  File "/home/tinmar/.local/lib/python3.10/site-packages/airflow/providers/google/common/hooks/base_google.py", line 247, in get_credentials_and_project_id
    raise AirflowException("Invalid key JSON.")
airflow.exceptions.AirflowException: Invalid key JSON.
[2023-02-09 10:59:50,638] {taskinstance.py:1395} INFO - Marking task as FAILED. dag_id=7_dataproc_subdags, task_id=create_cluster, execution_date=20230209T164200, start_date=20230209T165950, end_date=20230209T165950
[2023-02-09 10:59:50,648] {standard_task_runner.py:92} ERROR - Failed to execute job 15 for task create_cluster (Invalid key JSON.; 6647)
[2023-02-09 10:59:50,688] {local_task_job.py:156} INFO - Task exited with return code 1
